await 的抛出的异常可以被try catch捕获到 
对象的每一项用await 会顺序执行 其中一项报错 会阻断下面的所有
